{"record_time": "2020-09-14 14:38:20,020", "level": "ERROR", "log_msg": "Traceback (most recent call last):
  File "D:\Tool\Python38\lib\site-packages\tornado\web.py", line 1701, in _execute
    result = method(*self.path_args, **self.path_kwargs)
  File "d:\Project\python\bizhi\bizhi_message\handlers\Index.py", line 6, in get
    es= SevenElasticSearch()
  File "d:\Project\python\bizhi\bizhi_message\handlers\seven_elasticsearch.py", line 11, in __init__
    self.es=Elasticsearch(hostAddress,sniffer_timeout=600)
  File "D:\Tool\Python38\lib\site-packages\elasticsearch\client\__init__.py", line 227, in __init__
    self.transport = transport_class(_normalize_hosts(hosts), **kwargs)
  File "D:\Tool\Python38\lib\site-packages\elasticsearch\transport.py", line 127, in __init__
    self.set_connections(hosts)
  File "D:\Tool\Python38\lib\site-packages\elasticsearch\transport.py", line 182, in set_connections
    connections = list(zip(connections, hosts))
  File "D:\Tool\Python38\lib\site-packages\elasticsearch\transport.py", line 178, in _create_connection
    return self.connection_class(**kwargs)
  File "D:\Tool\Python38\lib\site-packages\elasticsearch\connection\http_urllib3.py", line 194, in __init__
    self.pool = pool_class(
  File "D:\Tool\Python38\lib\site-packages\urllib3\connectionpool.py", line 186, in __init__
    ConnectionPool.__init__(self, host, port)
  File "D:\Tool\Python38\lib\site-packages\urllib3\connectionpool.py", line 80, in __init__
    raise LocationValueError("No host specified.")
urllib3.exceptions.LocationValueError: No host specified.
", "host_ip": "192.168.28.42", "project_name": "bizhi_message"}
{"record_time": "2020-09-14 14:39:26,195", "level": "ERROR", "log_msg": "Traceback (most recent call last):
  File "D:\Tool\Python38\lib\site-packages\tornado\web.py", line 1701, in _execute
    result = method(*self.path_args, **self.path_kwargs)
  File "d:\Project\python\bizhi\bizhi_message\handlers\Index.py", line 6, in get
    es= SevenElasticSearch()
  File "d:\Project\python\bizhi\bizhi_message\handlers\seven_elasticsearch.py", line 11, in __init__
    self.es=Elasticsearch(hostAddress,sniffer_timeout=600)
  File "D:\Tool\Python38\lib\site-packages\elasticsearch\client\__init__.py", line 227, in __init__
    self.transport = transport_class(_normalize_hosts(hosts), **kwargs)
  File "D:\Tool\Python38\lib\site-packages\elasticsearch\transport.py", line 127, in __init__
    self.set_connections(hosts)
  File "D:\Tool\Python38\lib\site-packages\elasticsearch\transport.py", line 182, in set_connections
    connections = list(zip(connections, hosts))
  File "D:\Tool\Python38\lib\site-packages\elasticsearch\transport.py", line 178, in _create_connection
    return self.connection_class(**kwargs)
  File "D:\Tool\Python38\lib\site-packages\elasticsearch\connection\http_urllib3.py", line 194, in __init__
    self.pool = pool_class(
  File "D:\Tool\Python38\lib\site-packages\urllib3\connectionpool.py", line 186, in __init__
    ConnectionPool.__init__(self, host, port)
  File "D:\Tool\Python38\lib\site-packages\urllib3\connectionpool.py", line 80, in __init__
    raise LocationValueError("No host specified.")
urllib3.exceptions.LocationValueError: No host specified.
", "host_ip": "192.168.28.42", "project_name": "bizhi_message"}
{"record_time": "2020-09-14 14:42:28,989", "level": "ERROR", "log_msg": "Traceback (most recent call last):
  File "D:\Tool\Python38\lib\site-packages\tornado\web.py", line 1701, in _execute
    result = method(*self.path_args, **self.path_kwargs)
  File "d:\Project\python\bizhi\bizhi_message\handlers\Index.py", line 8, in get
    data= es.es_querypage("bizhi_setpiccomment_*",query,20)
  File "d:\Project\python\bizhi\bizhi_message\handlers\seven_elasticsearch.py", line 16, in es_querypage
    data= self.es.search(index, body,size,from_)
  File "D:\Tool\Python38\lib\site-packages\elasticsearch\client\utils.py", line 92, in _wrapped
    return func(*args, params=params, headers=headers, **kwargs)
TypeError: search() got multiple values for argument 'params'
", "host_ip": "192.168.28.42", "project_name": "bizhi_message"}
{"record_time": "2020-09-14 14:43:41,137", "level": "ERROR", "log_msg": "Traceback (most recent call last):
  File "D:\Tool\Python38\lib\site-packages\tornado\web.py", line 1701, in _execute
    result = method(*self.path_args, **self.path_kwargs)
  File "d:\Project\python\bizhi\bizhi_message\handlers\Index.py", line 8, in get
    data= es.es_querypage("bizhi_setpiccomment_*",query,20,0)
  File "d:\Project\python\bizhi\bizhi_message\handlers\seven_elasticsearch.py", line 16, in es_querypage
    data= self.es.search(index, body,size,from_)
  File "D:\Tool\Python38\lib\site-packages\elasticsearch\client\utils.py", line 92, in _wrapped
    return func(*args, params=params, headers=headers, **kwargs)
TypeError: search() got multiple values for argument 'params'
", "host_ip": "192.168.28.42", "project_name": "bizhi_message"}
{"record_time": "2020-09-14 14:43:45,547", "level": "ERROR", "log_msg": "Traceback (most recent call last):
  File "D:\Tool\Python38\lib\site-packages\tornado\web.py", line 1701, in _execute
    result = method(*self.path_args, **self.path_kwargs)
  File "d:\Project\python\bizhi\bizhi_message\handlers\Index.py", line 8, in get
    data= es.es_querypage("bizhi_setpiccomment_*",query,20,0)
  File "d:\Project\python\bizhi\bizhi_message\handlers\seven_elasticsearch.py", line 16, in es_querypage
    data= self.es.search(index, body,size,from_)
  File "D:\Tool\Python38\lib\site-packages\elasticsearch\client\utils.py", line 92, in _wrapped
    return func(*args, params=params, headers=headers, **kwargs)
TypeError: search() got multiple values for argument 'params'
", "host_ip": "192.168.28.42", "project_name": "bizhi_message"}
{"record_time": "2020-09-14 14:48:30,036", "level": "ERROR", "log_msg": "Traceback (most recent call last):
  File "D:\Tool\Python38\lib\site-packages\tornado\web.py", line 1701, in _execute
    result = method(*self.path_args, **self.path_kwargs)
  File "d:\Project\python\bizhi\bizhi_message\handlers\Index.py", line 6, in get
    es= SevenElasticSearch()
  File "d:\Project\python\bizhi\bizhi_message\handlers\seven_elasticsearch.py", line 12, in __init__
    self.es=Elasticsearch(hostAddress,sniffer_timeout=600)
  File "D:\Tool\Python38\lib\site-packages\elasticsearch\client\__init__.py", line 227, in __init__
    self.transport = transport_class(_normalize_hosts(hosts), **kwargs)
  File "D:\Tool\Python38\lib\site-packages\elasticsearch\transport.py", line 127, in __init__
    self.set_connections(hosts)
  File "D:\Tool\Python38\lib\site-packages\elasticsearch\transport.py", line 182, in set_connections
    connections = list(zip(connections, hosts))
  File "D:\Tool\Python38\lib\site-packages\elasticsearch\transport.py", line 178, in _create_connection
    return self.connection_class(**kwargs)
  File "D:\Tool\Python38\lib\site-packages\elasticsearch\connection\http_urllib3.py", line 194, in __init__
    self.pool = pool_class(
  File "D:\Tool\Python38\lib\site-packages\urllib3\connectionpool.py", line 186, in __init__
    ConnectionPool.__init__(self, host, port)
  File "D:\Tool\Python38\lib\site-packages\urllib3\connectionpool.py", line 80, in __init__
    raise LocationValueError("No host specified.")
urllib3.exceptions.LocationValueError: No host specified.
", "host_ip": "192.168.28.42", "project_name": "bizhi_message"}
{"record_time": "2020-09-14 14:49:12,935", "level": "ERROR", "log_msg": "Traceback (most recent call last):
  File "D:\Tool\Python38\lib\site-packages\tornado\web.py", line 1701, in _execute
    result = method(*self.path_args, **self.path_kwargs)
  File "d:\Project\python\bizhi\bizhi_message\handlers\Index.py", line 8, in get
    data= es.es_querypage("bizhi_setpiccomment_*",query,20,0)
  File "d:\Project\python\bizhi\bizhi_message\handlers\seven_elasticsearch.py", line 16, in es_querypage
    data= self.es.search(param_index, param_body,param_size,param_from_)
  File "D:\Tool\Python38\lib\site-packages\elasticsearch\client\utils.py", line 92, in _wrapped
    return func(*args, params=params, headers=headers, **kwargs)
TypeError: search() got multiple values for argument 'params'
", "host_ip": "192.168.28.42", "project_name": "bizhi_message"}
{"record_time": "2020-09-14 14:50:47,570", "level": "ERROR", "log_msg": "Traceback (most recent call last):
  File "D:\Tool\Python38\lib\site-packages\urllib3\connectionpool.py", line 426, in _make_request
    six.raise_from(e, None)
  File "<string>", line 3, in raise_from
  File "D:\Tool\Python38\lib\site-packages\urllib3\connectionpool.py", line 421, in _make_request
    httplib_response = conn.getresponse()
  File "D:\Tool\Python38\lib\http\client.py", line 1322, in getresponse
    response.begin()
  File "D:\Tool\Python38\lib\http\client.py", line 303, in begin
    version, status, reason = self._read_status()
  File "D:\Tool\Python38\lib\http\client.py", line 264, in _read_status
    line = str(self.fp.readline(_MAXLINE + 1), "iso-8859-1")
  File "D:\Tool\Python38\lib\socket.py", line 669, in readinto
    return self._sock.recv_into(b)
socket.timeout: timed out

During handling of the above exception, another exception occurred:

Traceback (most recent call last):
  File "D:\Tool\Python38\lib\site-packages\elasticsearch\connection\http_urllib3.py", line 228, in perform_request
    response = self.pool.urlopen(
  File "D:\Tool\Python38\lib\site-packages\urllib3\connectionpool.py", line 726, in urlopen
    retries = retries.increment(
  File "D:\Tool\Python38\lib\site-packages\urllib3\util\retry.py", line 379, in increment
    raise six.reraise(type(error), error, _stacktrace)
  File "D:\Tool\Python38\lib\site-packages\urllib3\packages\six.py", line 735, in reraise
    raise value
  File "D:\Tool\Python38\lib\site-packages\urllib3\connectionpool.py", line 670, in urlopen
    httplib_response = self._make_request(
  File "D:\Tool\Python38\lib\site-packages\urllib3\connectionpool.py", line 428, in _make_request
    self._raise_timeout(err=e, url=url, timeout_value=read_timeout)
  File "D:\Tool\Python38\lib\site-packages\urllib3\connectionpool.py", line 335, in _raise_timeout
    raise ReadTimeoutError(
urllib3.exceptions.ReadTimeoutError: HTTPConnectionPool(host='tianzhi-elastic.gao7.com', port=80): Read timed out. (read timeout=10)

During handling of the above exception, another exception occurred:

Traceback (most recent call last):
  File "D:\Tool\Python38\lib\site-packages\tornado\web.py", line 1701, in _execute
    result = method(*self.path_args, **self.path_kwargs)
  File "d:\Project\python\bizhi\bizhi_message\handlers\Index.py", line 8, in get
    data= es.es_querypage("bizhi_setpiccomment_*",query,20,0)
  File "d:\Project\python\bizhi\bizhi_message\handlers\seven_elasticsearch.py", line 16, in es_querypage
    data= self.es.search(index=param_index, body=param_body,size=param_size,from_=param_from_)
  File "D:\Tool\Python38\lib\site-packages\elasticsearch\client\utils.py", line 92, in _wrapped
    return func(*args, params=params, headers=headers, **kwargs)
  File "D:\Tool\Python38\lib\site-packages\elasticsearch\client\__init__.py", line 1622, in search
    return self.transport.perform_request(
  File "D:\Tool\Python38\lib\site-packages\elasticsearch\transport.py", line 355, in perform_request
    status, headers_response, data = connection.perform_request(
  File "D:\Tool\Python38\lib\site-packages\elasticsearch\connection\http_urllib3.py", line 240, in perform_request
    raise ConnectionTimeout("TIMEOUT", str(e), e)
elasticsearch.exceptions.ConnectionTimeout: ConnectionTimeout caused by - ReadTimeoutError(HTTPConnectionPool(host='tianzhi-elastic.gao7.com', port=80): Read timed out. (read timeout=10))
", "host_ip": "192.168.28.42", "project_name": "bizhi_message"}
