{"record_time": "2020-10-14 15:25:30,283", "level": "ERROR", "log_msg": "Traceback (most recent call last):
  File "D:\Tool\Python38\lib\site-packages\urllib3\connectionpool.py", line 426, in _make_request
    six.raise_from(e, None)
  File "<string>", line 3, in raise_from
  File "D:\Tool\Python38\lib\site-packages\urllib3\connectionpool.py", line 421, in _make_request
    httplib_response = conn.getresponse()
  File "D:\Tool\Python38\lib\http\client.py", line 1322, in getresponse
    response.begin()
  File "D:\Tool\Python38\lib\http\client.py", line 303, in begin
    version, status, reason = self._read_status()
  File "D:\Tool\Python38\lib\http\client.py", line 264, in _read_status
    line = str(self.fp.readline(_MAXLINE + 1), "iso-8859-1")
  File "D:\Tool\Python38\lib\socket.py", line 669, in readinto
    return self._sock.recv_into(b)
socket.timeout: timed out

During handling of the above exception, another exception occurred:

Traceback (most recent call last):
  File "D:\Tool\Python38\lib\site-packages\elasticsearch\connection\http_urllib3.py", line 228, in perform_request
    response = self.pool.urlopen(
  File "D:\Tool\Python38\lib\site-packages\urllib3\connectionpool.py", line 726, in urlopen
    retries = retries.increment(
  File "D:\Tool\Python38\lib\site-packages\urllib3\util\retry.py", line 379, in increment
    raise six.reraise(type(error), error, _stacktrace)
  File "D:\Tool\Python38\lib\site-packages\urllib3\packages\six.py", line 735, in reraise
    raise value
  File "D:\Tool\Python38\lib\site-packages\urllib3\connectionpool.py", line 670, in urlopen
    httplib_response = self._make_request(
  File "D:\Tool\Python38\lib\site-packages\urllib3\connectionpool.py", line 428, in _make_request
    self._raise_timeout(err=e, url=url, timeout_value=read_timeout)
  File "D:\Tool\Python38\lib\site-packages\urllib3\connectionpool.py", line 335, in _raise_timeout
    raise ReadTimeoutError(
urllib3.exceptions.ReadTimeoutError: HTTPConnectionPool(host='tianzhi-elastic.gao7.com', port=80): Read timed out. (read timeout=10)

During handling of the above exception, another exception occurred:

Traceback (most recent call last):
  File "D:\Tool\Python38\lib\site-packages\tornado\web.py", line 1703, in _execute
    result = await result
  File "D:\Tool\Python38\lib\site-packages\seven_framework\web_tornado\base_handler\base_handler.py", line 48, in get
    await asyncio.get_event_loop().run_in_executor(self.executor,
  File "D:\Tool\Python38\lib\concurrent\futures\thread.py", line 57, in run
    result = self.fn(*self.args, **self.kwargs)
  File "d:\Project\python\bizhi\bizhi_message\handlers\server\sdk_message.py", line 42, in get_async
    message_list=es.es_querypage(es_body,pageSize,from_)
  File "d:\Project\python\bizhi\bizhi_message\handlers\seven_elasticsearch.py", line 19, in es_querypage
    data= self.es.search(index=self.index_name,doc_type=self.doc_type_name, body=param_body,size=param_size,from_=param_from_)
  File "D:\Tool\Python38\lib\site-packages\elasticsearch\client\utils.py", line 92, in _wrapped
    return func(*args, params=params, headers=headers, **kwargs)
  File "D:\Tool\Python38\lib\site-packages\elasticsearch\client\__init__.py", line 1622, in search
    return self.transport.perform_request(
  File "D:\Tool\Python38\lib\site-packages\elasticsearch\transport.py", line 355, in perform_request
    status, headers_response, data = connection.perform_request(
  File "D:\Tool\Python38\lib\site-packages\elasticsearch\connection\http_urllib3.py", line 240, in perform_request
    raise ConnectionTimeout("TIMEOUT", str(e), e)
elasticsearch.exceptions.ConnectionTimeout: ConnectionTimeout caused by - ReadTimeoutError(HTTPConnectionPool(host='tianzhi-elastic.gao7.com', port=80): Read timed out. (read timeout=10))
", "host_ip": "192.168.28.42", "project_name": "bizhi_message"}
